Workbook

Sheet Cover
A5: Data file to accompany paper "Systemic Banking Crises Revisited"
A6: by Luc Laeven and Fabian Valencia (2018)

Sheet Crisis Years
A1: Country | B1: Systemic Banking Crisis (starting date)
A3: Albania | B3: 1994
A4: Algeria | B4: 1990
A5: Angola
A6: Argentina | B6: 1980, 1989, 1995, 2001
A7: Armenia | B7: 1994
A8: Australia
A9: Austria | B9: 2008
A10: Azerbaijan | B10: 1995
A11: Bangladesh | B11: 1987
A12: Barbados
A13: Belarus | B13: 1995
A14: Belgium | B14: 2008
A15: Belize
A16: Benin | B16: 1988
A17: Bhutan
A18: Bolivia | B18: 1986, 1994
A19: Bosnia and Herzegovina | B19: 1992
A20: Botswana
A21: Brazil | B21: 1990, 1994
A22: Brunei
A23: Bulgaria | B23: 1996
A24: Burkina Faso | B24: 1990
A25: Burundi | B25: 1994
A26: Cambodia
A27: Cameroon | B27: 1987, 1995
A28: Canada
A29: Cape Verde | B29: 1993
A30: Central African Rep. | B30: 1976, 1995
A31: Chad | B31: 1983, 1992
A32: Chile | B32: 1976, 1981
A33: China, P.R. | B33: 1998
A34: Colombia | B34: 1982, 1998
A35: Comoros
A36: Congo, Dem. Rep. of | B36: 1983, 1991, 1994
A37: Congo, Rep. of | B37: 1992
A38: Costa Rica | B38: 1987, 1994
A39: Côte d’Ivoire | B39: 1988
A40: Croatia | B40: 1998
A41: Czech Republic | B41: 1996
...

Sheet Crisis Frequency
A1: Year | B1: Banking crisis (number) | C1: Currency crisis (number) | D1: Sovereign debt crisis (number) | E1: Twin crisis (number) 1/ | F1: Triple crisis (number) 2/
A2: 1970
A3: 1971 | C3: 1
A4: 1972 | C4: 5
A5: 1973 | C5: 1
A6: 1974
A7: 1975 | C7: 5
A8: 1976 | B8: 2 | C8: 4 | D8: 1
A9: 1977 | B9: 1 | C9: 1 | D9: 1
A10: 1978 | C10: 5 | D10: 3
A11: 1979 | C11: 3 | D11: 2
A12: 1980 | B12: 3 | C12: 4 | D12: 3 | E12: 3
A13: 1981 | B13: 3 | C13: 10 | D13: 6 | E13: 2 | F13: 1
A14: 1982 | B14: 5 | C14: 5 | D14: 9 | E14: 2 | F14: 1
A15: 1983 | B15: 8 | C15: 12 | D15: 9 | E15: 2 | F15: 1
A16: 1984 | B16: 1 | C16: 10 | D16: 4
A17: 1985 | B17: 2 | C17: 10 | D17: 3
A18: 1986 | B18: 1 | C18: 4 | D18: 3
A19: 1987 | B19: 6 | C19: 6 | E19: 1
A20: 1988 | B20: 7 | C20: 5 | D20: 1
A21: 1989 | B21: 4 | C21: 8 | D21: 3 | E21: 1 | F21: 1
A22: 1990 | B22: 6 | C22: 10 | D22: 2 | E22: 3
A23: 1991 | B23: 10 | C23: 6 | E23: 1
A24: 1992 | B24: 8 | C24: 6 | D24: 1 | E24: 2
A25: 1993 | B25: 7 | C25: 8 | E25: 1
A26: 1994 | B26: 11 | C26: 20 | E26: 3
A27: 1995 | B27: 13 | C27: 4 | E27: 4
A28: 1996 | B28: 4 | C28: 6 | E28: 2
A29: 1997 | B29: 7 | C29: 7 | E29: 5
A30: 1998 | B30: 8 | C30: 10 | D30: 2 | E30: 3 | F30: 3
A31: 1999 | C31: 7 | D31: 2
A32: 2000 | B32: 2 | C32: 4 | E32: 1
A33: 2001 | B33: 1 | C33: 3 | D33: 2 | E33: 1 | F33: 1
A34: 2002 | B34: 1 | C34: 5 | D34: 4 | E34: 1 | F34: 1
A35: 2003 | B35: 1 | C35: 4 | D35: 1 | E35: 1 | F35: 1
A36: 2004 | C36: 1 | D36: 1
A37: 2005 | C37: 1
A38: 2006
A39: 2007 | B39: 2 | C39: 1 | D39: 1
A40: 2008 | B40: 22 | C40: 3 | D40: 2 | E40: 2
...

Sheet Crisis Resolution and Outcomes
A1: Country | B1: Start | C1: End | D1: Output loss | E1: Fiscal Costs (% of GDP) | F1: Fiscal Costs, net (% of GDP) | G1: Fiscal cost (% of financial sector assets) | H1: Peak liquidity | I1: Liquidity support | J1: Peak NPLs | K1: Increase in public debt
A2: Albania | B2: 1994 | C2: 1994 | D2: … | E2: ... | F2: ... | G2: ... | H2: 7.615962 | I2: ... | J2: 26.8 | K2: ...
A3: Algeria | B3: 1990 | C3: 1994 | D3: 41.392253 | E3: ... | F3: ... | G3: ... | H3: 37.56032 | I3: 29.85246 | J3: 30 | K3: 19.10056
A4: Argentina | B4: 1980 | C4: 1982 | D4: 58.171235 | E4: 55.1 | F4: 55.1 | G4: 213.89751 | H4: 64.64586 | I4: 62.21225 | J4: 9 | K4: 33.14739
A5: Argentina | B5: 1989 | C5: 1991 | D5: 12.629947 | E5: 6 | F5: 6 | G5: 21.606049 | H5: 151.5721 | I5: 135.665 | J5: 27 | K5: -21.29261
A6: Argentina | B6: 1995 | C6: 1995 | D6: 0 | E6: 2 | F6: 2 | G6: 8.550663 | H6: 71.3528 | I6: 62.99766 | J6: 17 | K6: 8.69467
A7: Argentina | B7: 2001 | C7: 2003 | D7: 70.974199 | E7: 9.6 | F7: 9.5846645 | G7: 28.094822 | H7: 22.85839 | I7: 22.64661 | J7: 20.1 | K7: 81.88721
A8: Armenia | B8: 1994 | C8: 1994 | D8: … | E8: ... | F8: ... | G8: ... | H8: 41.37691 | I8: 22.99402 | J8: ... | K8: ...
A9: Austria | B9: 2008 | C9: 2012 | D9: 19.215918 | E9: =+'Additional Details'!F47*100 -> 5.15 | F9: 1.64 | G9: 1.6435314 | H9: 10.02 | I9: 6.41 | J9: =+'Additional Details'!F45*100 -> 4.1 | K9: 19.8
A10: Azerbaijan | B10: 1995 | C10: 1995 | D10: ... | E10: ... | F10: ... | G10: ... | H10: 127.5802 | I10: 84.46377 | J10: ... | K10: 0.89603
A11: Bangladesh | B11: 1987 | C11: 1987 | D11: 0 | E11: ... | F11: ... | G11: ... | H11: 25.96208 | I11: 2.82342 | J11: 20 | K11: 3.4759
A12: Belarus | B12: 1995 | C12: 1995 | D12: ... | E12: ... | F12: ... | G12: ... | H12: 35.7598 | I12: ... | J12: ... | K12: -16.45655
A13: Belgium | B13: 2008 | C13: 2012 | D13: 15.732718 | E13: =+'Additional Details'!G47*100 -> 6.15 | F13: 0.46 | G13: 1.6283828 | H13: 13.69 | I13: 9.67 | J13: =100*'Additional Details'!G45 -> 4.24 | K13: 22.2
A14: Benin | B14: 1988 | C14: 1992 | D14: 14.917588 | E14: 17 | F14: ... | G14: 64.320847 | H14: 99.64091 | I14: 48.62441 | J14: 80 | K14: 5.67801
A15: Bolivia | B15: 1986 | C15: 1986 | D15: 49.191735 | E15: ... | F15: ... | G15: ... | H15: 57.52545 | I15: 25.92482 | J15: 30 | K15: -107.2825
A16: Bolivia | B16: 1994 | C16: 1994 | D16: 0 | E16: 6 | F16: 2.6533333 | G16: 15.193719 | H16: 31.92642 | I16: 12.89265 | J16: 6.2 | K16: -19.21072
A17: Bosnia and Herzegovina | B17: 1992 | C17: 1996 | D17: ... | E17: ... | F17: ... | G17: ... | H17: ... | I17: ... | J17: ... | K17: ...
A18: Brazil | B18: 1990 | C18: 1994 | D18: 62.295604 | E18: 0 | F18: 0 | G18: 0 | H18: 11.26261 | I18: 10.71347 | J18: ... | K18: -22.64
A19: Brazil | B19: 1994 | C19: 1998 | D19: 0 | E19: 13.2 | F19: 10.2 | G19: 28.596188 | H19: 20.11846 | I19: 17.61162 | J19: 16 | K19: -33.77793
A20: Bulgaria | B20: 1996 | C20: 1997 | D20: 59.510493 | E20: 14 | F20: 13.9 | G20: 21.370783 | H20: 17.30571 | I20: 9.93675 | J20: 75 | K20: -30.07973
A21: Burkina Faso | B21: 1990 | C21: 1994 | D21: ... | E21: ... | F21: ... | G21: ... | H21: 9.3824 | I21: 4.51769 | J21: 16 | K21: 8.92432
A22: Burundi | B22: 1994 | C22: 1998 | D22: 121.192 | E22: ... | F22: ... | G22: ... | H22: 23.44168 | I22: 18.25261 | J22: 25 | K22: 10.85286
A23: Cameroon | B23: 1987 | C23: 1991 | D23: 105.52664 | E23: ... | F23: ... | G23: ... | H23: 59.10603 | I23: 40.85175 | J23: 65 | K23: 17.96692
A24: Cameroon | B24: 1995 | C24: 1997 | D24: 8.0982519 | E24: ... | F24: ... | G24: ... | H24: 12.31134 | I24: 6.16095 | J24: 30 | K24: -1.06627
A25: Cape Verde | B25: 1993 | C25: 1993 | D25: 0 | E25: ... | F25: ... | G25: ... | H25: 3.967447 | I25: ... | J25: 30 | K25: 18.15971
A26: Central African Rep | B26: 1976 | C26: 1976 | D26: 0 | E26: ... | F26: ... | G26: ... | H26: 90.84164 | I26: 10.4593 | J26: ... | K26: -4.77751
A27: Central African Rep | B27: 1995 | C27: 1996 | D27: 8.9569594 | E27: ... | F27: ... | G27: ... | H27: 24.83221 | I27: 20.94306 | J27: 40 | K27: -16.26852
A28: Chad | B28: 1983 | C28: 1983 | D28: 0 | E28: ... | F28: ... | G28: ... | H28: 199.305 | I28: 41.31468 | J28: ... | K28: -7.16883
A29: Chad | B29: 1992 | C29: 1996 | D29: 0 | E29: ... | F29: ... | G29: ... | H29: 120.8667 | I29: 41.38313 | J29: 35 | K29: 27.0806
A30: Chile | B30: 1976 | C30: 1976 | D30: 19.89855 | E30: ... | F30: ... | G30: ... | H30: 32.20038 | I30: 23.63696 | J30: ... | K30: -69.52382
A31: Chile | B31: 1981 | C31: 1985 | D31: 8.6097452 | E31: 42.9 | F31: 16.8 | G31: 134.31433 | H31: 61.22512 | I31: 52.6979 | J31: 35.6 | K31: 87.8976
A32: China, Mainland | B32: 1998 | C32: 1998 | D32: 19.398311 | E32: 18 | F32: ... | G32: 19.53125 | H32: 62.01519 | I32: 7.19216 | J32: 20 | K32: 11.15775
A33: Colombia | B33: 1982 | C33: 1982 | D33: 46.959534 | E33: 5 | F33: 5 | G33: 16.496206 | H33: 21.06028 | I33: 7.73772 | J33: 4.1 | K33: 16.57043
A34: Colombia | B34: 1998 | C34: 2000 | D34: 43.398161 | E34: 6.3 | F34: 2.54 | G34: 15.897047 | H34: 5.073536 | I34: 4.29109 | J34: 14 | K34: 15.40799
A35: Congo, Dem Rep | B35: 1983 | C35: 1983 | D35: 1.3754204 | E35: ... | F35: ... | G35: ... | H35: 19.95647 | I35: 18.91813 | J35: ... | K35: 39.45382
A36: Congo, Dem Rep | B36: 1991 | C36: 1994 | D36: 129.54675 | E36: ... | F36: ... | G36: ... | H36: 44.69853 | I36: 30.17046 | J36: ... | K36: 42.1884
A37: Congo, Dem Rep | B37: 1994 | C37: 1998 | D37: 78.991939 | E37: ... | F37: ... | G37: ... | H37: 77.25292 | I37: 77.11886 | J37: 75 | K37: 39.25775
A38: Congo, Rep | B38: 1992 | C38: 1994 | D38: 47.359838 | E38: ... | F38: ... | G38: ... | H38: 30.73201 | I38: 16.58411 | J38: ... | K38: 103.4631
A39: Costa Rica | B39: 1987 | C39: 1991 | D39: 0 | E39: ... | F39: ... | G39: ... | H39: 20.17417 | I39: 6.09581 | J39: ... | K39: -27.54878
A40: Costa Rica | B40: 1994 | C40: 1995 | D40: 0 | E40: ... | F40: ... | G40: ... | H40: 15.1952 | I40: 6.34947 | J40: 32 | K40: 4.75884
...

Sheet Additional Details
A1: Country name | B1: Argentina | C1: Argentina | D1: Argentina | E1: Argentina | F1: Austria | G1: Belgium | H1: Bolivia | I1: Brazil | J1: Brazil | K1: Bulgaria | L1: Chile | M1: Colombia | N1: Colombia | O1: Cote d'Ivoire | P1: Croatia | Q1: Czech Republic | R1: Cyprus | S1: Denmark | T1: Dominican Republic | U1: Ecuador | V1: Estonia | W1: Finland | X1: France | Y1: Germany | Z1: Ghana | AA1: Greece | AB1: Hungary | AC1: Iceland | AD1: Indonesia | AE1: Ireland | AF1: Italy | AG1: Jamaica | AH1: Japan | AI1: Kazakhstan | AJ1: Korea | AK1: Latvia | AL1: Latvia | AM1: Lithuania | AN1: Luxembourg | AO1: Malaysia | AP1: Mexico | AQ1: Moldova | AR1: Mongolia | AS1: Netherlands | AT1: Nicaragua | AU1: Nigeria | AV1: Norway | AW1: Paraguay | AX1: Philippines | AY1: Portugal | AZ1: Russia | BA1: Russia | BB1: Slovenia | BC1: Spain | BD1: Sri Lanka | BE1: Sweden | BF1: Sweden | BG1: Switzerland | BH1: Thailand | BI1: Turkey | BJ1: Ukraine | BK1: Ukraine | BL1: Ukraine | BM1: United Kingdom | BN1: United States | BO1: Uruguay | BP1: Venezuela | BQ1: Vietnam
A2: Banking crisis start date | B2: 29281 | C2: 32843 | D2: 34700 | E2: 37196 | F2: 39692 | G2: 39692 | H2: 34639 | I2: 32905 | J2: 34669 | K2: 35065 | L2: 29891 | M2: 30133 | N2: 35947 | O2: 1988 | P2: 35855 | Q2: 35217 | R2: 40695 | S2: 39692 | T2: 37712 | U2: 36008 | V2: 33909 | W2: 33482 | X2: 39692 | Y2: 39692 | Z2: 29952 | AA2: 39692 | AB2: 39692 | AC2: 39692 | AD2: 35735 | AE2: 39692 | AF2: 39692 | AG2: 35400 | AH2: 35735 | AI2: 39692 | AJ2: 35643 | AK2: 34790 | AL2: 39692 | AM2: 35034 | AN2: 39692 | AO2: 35612 | AP2: 34669 | AQ2: 41944 | AR2: 39692 | AS2: 39692 | AT2: 36739 | AU2: 40026 | AV2: 33512 | AW2: 34820 | AX2: 35612 | AY2: 39692 | AZ2: 36008 | BA2: 39692 | BB2: 39692 | BC2: 39692 | BD2: 1989 | BE2: 33482 | BF2: 39692 | BG2: 39692 | BH2: 35612 | BI2: 36831 | BJ2: 36008 | BK2: 39692 | BL2: 41671 | BM2: 39326 | BN2: 39417 | BO2: 37258 | BP2: 34335 | BQ2: 35735
A3: Date when crisis became systemic | B3: =+B26 -> 29342 | C3: 32843 | D3: 34700 | E3: 37226 | F3: =+F21 -> 39783 | G3: =+G21 -> 39722 | H3: 34639 | I3: 32905 | J3: 34669 | K3: 35217 | L3: 30376 | M3: 30133 | N3: 35947 | O3: 1988 | P3: 35855 | Q3: 35217 | R3: 41061 | S3: =+S21 -> 39845 | T3: 37712 | U3: 36130 | V3: 33909 | W3: 34001 | Y3: 40087 | Z3: 29952 | AA3: 39934 | AC3: 39722 | AD3: 35765 | AE3: 39814 | AG3: 35462 | AH3: 35735 | AI3: 40422 | AJ3: 35735 | AK3: 34790 | AL3: =+AL21 -> 39783 | AM3: 35034 | AN3: 39692 | AO3: 35855 | AP3: 34700 | AQ3: 41944 | AR3: 40118 | AS3: 39722 | AT3: 36892 | AU3: 40817 | AV3: 33512 | AW3: 34881 | AX3: 35855 | AZ3: 36161 | BC3: 40634 | BD3: 1989 | BE3: 33848 | BH3: 35704 | BI3: 36861 | BJ3: 36130 | BK3: 39934 | BL3: 41974 | BM3: 39753 | BN3: 39722 | BO3: 37347 | BP3: 34335 | BQ3: 36069
A4: Brief description of crisis | B4: A banking crisis erupted in March 1980 as a number of financial institutions overextended themselves and were forced to rely heavily on Central Bank financial assistance when faced with deposit withdrawals. The failed institutions included the largest investment bank and the second largest private commercial bank. More than 70 institutions—accounting for 16 percent of commercial bank assets and 35 percent of finance company assets—were liquidated or subjected to central bank intervention. In total, the system shrunk by 86 financial institutions between 1980 and 1982. To a large extent, the crisis was induced by private entities, unable to honor their financial commitments, similar to what happened in other countries in the region. Borrowers were aided by extensions of exchange rate guarantees and debt restructuring. The consequence was a severe economic crisis. Real GDP reached, by 1982, a cumulative decline of 10 percent. With the sharp increase in factor payments abroad and the deterioration in the terms of trade, real per capita income reached its lowest level in about ten years. Inflation increased sharply, investment, real wages, and industrial employment plummetted. | C4: During the 1980s, a decline in the availability of external resources led to an increased recourse to domestic financing. Despite the use of various devices, the Government found it increasingly difficult to place securities in the market and had to rely on financing from the Central Bank. To fund its credit operations the Central Bank imposed reserve and investment requirements on deposits. They were replaced by frozen deposits at the Central Bank in several occasions, e.g., in October 1980 and in August 1988. In addition, central bank debt grew through the issuance of short-term paper (CEDEPS) to financial entities for purposes of monetary control. The deterioration of the fiscal situation during the first half of 1989 resulted in increasing pressure on the Central Bank to accommodate the borrowing needs of the nonfinancial public sector, particularly as new debt sales fell short of the maturities falling due. The Central Bank accelerated its placement of CEDEPS which by midyear were being issued to finance interest payments on the Central Bank's own debt. On January 1, 1990, the Government announced the bond conversion of time deposits and public sector debt coming due in 1990 (BONEX 89). The debt conversion brought a brief period of calm, but flight from the austral reappeared in mid-January. At the same time, the central bank kept liquidity tight and by end-February interest rates reached over 1000 percent a mongth for 7-day term deposits. A new economic package was announced in March 1990 bringing some calm to the system, until convertibility was adopted a year later. | D4: The convertibility plan implemented since early 1991 brought about a process of remonetization and re-intermediation, aided by the elimination of taxes on financial transactions and by the gradual reduction and harmoniation of reserve requirements. As a result, deposits and external lines of credit surged, leading to a rapid increase in bank credit. At the same time, the economy expanded robustly, but the real exchange rate appreciated and the current account deficit increased. The banking industry was highly segmented, with the state-owned provincial banks suffering from high non-performing loans as they were used as an important source of funds for financing the provincial governments' deficits. With the Mexican devaluation, a small bond trader experienced a liquidity squeeze pushing it to closure by mid January, 1995. This development persuaded most banks to cut credit to bond traders, which in turn affected banks with large bond and open trading positions. Furthermore, provincial banks were having difficulties in raising funds--problems which began even before the mexican devaluation--and people started moving funds towards larger banks, in particularly foreign, perceived as more solvent, but by March, capital flights intensified. Several measures were implemented at alleviating liquidity pressures. By end of 1995 deposits recovered to pre-crisis levels, although lending took longer than a year to recover. In the end, the fiscal cost of the crisis was small. Eight banks were suspended and three banks collapsed. Out of the 205 banks in existence as of end of 1994, 63 exited the market through mergers, absortions, or liquidation by end 1997. | E4: Argentina had accumulated important fiscal imbalances, and experienced a competitiveness problems following the crisis in Brazil. Restructuring of public debt and the announcement of a modification to the parity under the convertibility plan (from being pegged to the dollar, to being pegged to a basket composed of the US dollar and Euro) initiated bank runs by mid-2001, which intensified towards the second half of the year, leading to a deposit freeze, a bank holiday, riots, and major political instability in December 2001. | H4: During 1988-94 bank credit to the private sector grew by 30 percent a year on average in U.S. dollar terms, reflecting strong growth in dollar bank deposits resulting from a reflow of flight capital and high domestic interest rates. At the same time, the prudential regulations and bank supervision were not yet strong enough to maintain the quality of bank portfolios. These difficulties were compounded at the end of 1994 and during 1995 by several financial shocks, including the failure of two institutions and the failure of Banco Boliviano Americano's (BBA) shareholders to honor the obligations of Banco Boliviano International (BBI) offshore. These shocks induced large capital flight during January-April 1995 and August-September 1995. Other 4 banks (representing a third of the assets of the industry) were recapitalized and restructured. | I4: The stance of monetary policy was expansionary throughout 1988-90 and the first half of 1991. As a result, the monetary aggregates expanded rapidly: in 1988-90, the net domestic assets of the Central Bank rose by almost 1,400 percent a year while those of the banking system grew at an average rate of 1,200 percent a year. During the same period, the public increasingly reduced its holdings of financial assets in real terms: overall liquidity, including government securities held by the public, fell from the equivalent of 23 l/2 percent of GDP in December 1987 to 19 percent of GDP in June 1991. Virtually all liquidity assistance granted to financial entities went to public institutions. | J4: The Brazilian economy entered a new phase with the implementation of the “Plan Real” in July 1994. The plan triggered a major process of structural changes, which aimed primarily at lowering inflation. With this process, a remonetization of the economy took place and with it, liabilities and assets of banks expanded rapidly—loans to private sector grew by 60% during the first year of the plan--despite higher reserve requirements. At the same time a sharp deterioration in the trade account took place, to which the central bank responded by raising interest rates and imposed credit restrictions. The financial situation of banks weakened as bad loans increased noticeably and also because they lost their inflation revenues. The problems were particularly more acute at public banks. For federal banks, the ratio of loans in arrears and in liquidation to total loans increased from 15.4 percent in June 1994 to 22.4 percent at end-1995, and to slightly more than 30 percent in October 1996. For state-owned banks the ratio increased from 8 percent to almost 12 percent and more than 14 percent for the same dates. For private banks, the ratio increased from 5 percent in June 1994 to 9 percent in December 1995. The problems in the banking sector triggered a restructuring of public banks and the resolution of private institutions. Most of the closures were medium to small-sized banks, while large banks were resolved under a “good bank/bad bank” approach. | K4: The 1996 banking crisis had its roots in bad loans made during 1991-1995, but the deepening insolvency of the system was not reflected in sustained liquidity problems until the second half of 1994. Two ailing state banks required ongoing refinancing from the Bulgarian National Bank (BNB) and the State Savings Bank (SSB) until they were bailed out in mid-1995. The public began to lose confidence in banks after the collapse of pyramid schemes in some cities, and in response to reports on the ill health of other banks. In late 1995 withdrawals of deposits ,especially from First Private Bank (the largest private bank), were reflected in substantial BNB refinancing and falling foreign reserves. Contributing to the runs on banks was the announcement of a deposit insurance scheme by the BNB, where cover was for the first time explicitly limited to the equivalent of US$750 per depositor. Public fears of a blocking of foreign exchange deposits developed as BNB reserves declined, and withdrawals of foreign exchange deposits totaled almost 40% of total during 1996. | L4: Before 1973, the Chilean economy was characterized by hyperinflation and serious imbalances. In the following years, a stabilization plan was implemented that brought real GDP growth to 7.2% on average between 1976 and 1981, inflation was brought down to 9.5% in 1981 and unemployment lowered to 10.4% in 1980. Meanwhile, banking measures were implemented since 1973 aiming at liberalizing the financial system by eliminating interest rates controls, credit allocation controls, reserve requirements were lowered and banks privatized. As a result, credit grew rapidly and foreign borrowing increased significantly. Foreign liabilities went up from 14.4% of total in 1978 to 35.8% of total in 1982. The exchange-rate stabilization policy brougth about a significant overvaluation of the peso, tripling of the private external debt between 1979 and 1981, an increase of the current account deficit to 18.9% in 1981. By the end of 1981, a 6-year expansionary period ended abruptly. High international interest rates, a world recession, lower copper prices, and an abrupt cut of voluntary foreign credit to Latin America pushed Chile into a costly economic crisis. The problems were agravated by unsound financial practices among banks, which included substantial connected lending ranging from 12 to 45% of the total loans portfolio. The financial system was affected in two waves. The first one in 1981-82 including 11 liquidations (banks and finance companies), where all depositors were protected. The second one in 1983, involved liquidations and rehabilitations and in the liquidation cases, domestic depositors were compensated only partially. While foreign creditors were offered the same compensation, they threatened by cutting trade credit lines and were ultimately restructured under the external debt restructuring plan. | M4: The concentration of ownership of the banking sector was high, which kept competition low in an environment where lending practices were unsound. During the early 1980’s, the economic downturn affected also profitability of banks. They came under pressure as the 1981 recession intensified. This, in turn, caused a sharp deterioration in asset quality through an increase in defaults. Colombia began experiencing capital outflows. Subsequent bank failures and nationalizations generated widespread decline in public confidence which led to the nationalization of 80% of the banking system. | N4: Capital account reversal during the first half of 1998 triggered by pressures in emerging markets led to a response from the Central Bank oriented towards defending the currency. As a result, interest rates increased sharply in real terms, harming the quality of banks' loan portfolios and putting a downward pressure on asset prices and hence on the value of collateral, especially real estate. The already weak large public banks faced a severe asset quality deterioration which spread (although in a somewhat less severe way) to private banks and other financial entities. | O4: The recession of 1987 and problems with the cocoa and coffee markets (main exports) substantially increased private sector's non-performing loans. These problems were aggravated by a large amount of nonperforming loans in the public enterprise sectors, the large accumulation of government payment arrears, the substantial decline in public and private deposits in the banking system, reduction in credit lines from abroad, and poor management in some banks. The Government thus initiated in late 1991 a financial sector adjustment program (PASFI) supported by a sectoral adjustment loan of the World Bank. The program provided for the rehabilitation of the commercial banking sector through the settlement of government payments arrears, the recapitalization of banks, and the adequate provisioning for their loan losses. The program also involved the liquidation of 6 banks, including the National Agricultural Development Bank (BNDA); the reform of the judicial framework for banking activities; and the restructuring of nonbank financial institutions, including the Abidjan Stock Exchange and the insurance sector. | P4: The introduction of a market-oriented legal framework in the early 1990s, led to significant progress in establishing a modern banking system. The banking sector expanded vigorously until end-1997. Meanwhile, the incentives for sound bank behavior had not yet been fully established, coupled with bad debt problems inherited from the old regime. These weaknesses were in part addressed with the Bank rehabilitation plan (Law of 1994) implemented in 1996-1997. Four state-owned banks, accounting for 46 percent of total bank assets (as of 1995) entered rehabilitation, with an overall cost of 6.1% of GDP. However, a new wave of problems began in March 1998 with the failure of the 5th largest bank, Dubrovacka (5% of total assets). Problems at this bank triggered political turmoil, which in turn induced runs at other banks, perceived indirectly related to Dubrovacka. In july 1998, the sixth largest bank ran into problems and several medium- and small-sized institutions experienced liquidity difficulties in the fall of 1998 and early 1999 as well. | Q4: Following the transition from a central-planning system, Czech Republic embarked on a first phase of bank rehabilitation during 91-93, characterized by consolidation and strengthening of large banks through purchase of bad assets by the bank restructuring agency (Consolidation Bank). However, not all problems were addressed and in 1994 a small bank failed (Banka Bohemia), due to fraud. While all depositors were covered, a partial deposit insurance coverage was introduced shortly after this first failure. The likelihood of facing material losses triggered runs at other small banks, until by the end of 1995 2 small banks failed (ceska and AB Banka), which triggered a second phase of bank restructuring, aimed at 18 small banks (9% of industry's assets). | R4: Bank asset quality deteriorated as the real estate boom turned to bust and growth came to a halt. Furthermore, banks in Cyprus were heavily exposed to Greece with banks’ holdings of Greek loans and Greek government bonds amounting to about 130 percent and 40 percent of Cyprus’s GDP respectively at end-June 2011. The intensification of the Greek crisis led to an erosion of confidence in Cypriot banks and the sovereign, which lost market access in May 2011. The banks experienced deposit outflows as discussions on a restructuring of Greek debt started in mid-2011 and had to resort to emergency liquidity assistance from the Central Bank of Cyprus. As a result of the Greek debt restructuring, BoC and Laiki suffered combined losses of 25 percent of GDP. BoC managed to attract capital to cover for the loss, Laiki required public support of €2 billion (10 percent of GDP) in 2012. In early 2013, an independent due-diligence bottom-up assessment of banks’ loan books found that both Laiki and BoC were economically insolvent. Total capital needs of the sector were estimated at above €10 billion (60 percent of GDP). The authorities resorted later to imposing a bank holiday and deposit freezes and further recapitalizations to restore financial stability. | T4: In late 2002, a large Bank, Baninter, begins having liquidity problems and requests assistance from the Central Bank. Withdrawals intensified throughout the first quarter of 2003 until the bank was intervened in early april. A due dilligence on the bank revealed a large amount of unregistered deposits, in an amount that implied that Baninter's size was more than three times its declared size. Fearing widespread runs on other banks, the authorities announced that all legitimate deposits would be covered, by swapping them with Central Bank Certificates, ultimately, all depositors including those of the offshore affiliate were covered. The collapse of Baninter triggered runs at two other smaller banks Bancredito and Mercantil, rumored to have being engaged in similar fraudulent activities. The good assets of the banks were sold a few months later. The massive liquidity support provided to Baninter (15% of GDP) and the other two banks implied a substantial monetary expansion that led to a significant decline in the value of the currency. As a consequence, public sector debt increased in about 20 percentage points of GDP. | U4: Starting in the early 1995 and following a string of exogenous events (most notably the hostilities with Peru, domestic political problems, and the “tequila” crisis), Ecuador experienced a stop and reversal of capital inflows, which triggered financial instability and dived the country into a period of economic stagnation, featuring increasing macroeconomic imbalances, in a great extent correlated with the evolution of the external oil prices. In this environment, macroeconomic performance deteriorated during the second half of the decade creating conditions that contributed decisively to the late 1990s financial crisis. The spark was the failure of a small bank in April 1998, which triggered runs on other banks. It gained momentum in August when another bank failed, followed by the request of liquidity assistance from the largest bank. 16 out of 40 banks ran into problems, including most of the largest institutions. | V4: After establishing the currency board, the environment for banking business in Estonia changed significantly. In the fall of 1992, a number of banks became illiquid. Eesti Pank provided liquidity assistance at first, but later in November decided to suspend the operations of the three largest banks (30 percent of the system). The causes varied: Tartu Commercial Bank had engaged in substantial connected lending, ending in insolvency; Northern Estonian Bank and Union Baltic Bank had their assets frozen at the Vneshekonombank in Moscow. Tartu Commercial Bank was closed and liquidated whereas the other two credit institutions were merged and recapitalized by the government. The new entity was called North Estonia Bank. After these measures, the system remained unstable in 1993, but serious problems only showed up in smaller banks. 20 small credit institutions were either liquidated or merged. The total number of Estonian credit institutions was almost halved in the course of one year. In the spring of 1994 the state treasury decided to withdraw deposits from Social Bank (20 percent of the system) which had acted as the government’s main fiscal agent. The withdrawal of resources triggered serious liquidity and solvency problems. The Social Bank quickly became the largest borrower on the interbank market, which, in turn, became Overburdened. The bank was liquidated in May 1995. The bulk of deposits were transferred to the North Estonia Bank while the remainder became an asset recovery agency. Unlike in the earlier episodes, all creditors were fully compensated. | W4: The three Nordic countries went through a financial liberalization process that led to a lending boom. However, they also suffered the adverse consequences of higher German interest rates. In the case of Finland, the problems were exacerbated by the collapse of exports to the Soviet Union. The first bank in trouble was Skopbank, which was taken over by the Central Bank in September 1991, although it had been under intense surveillance since 1989. No Banks were closed, but all large banks faced serious solvency problems. | Z4: During most of the 80's Ghana suffered severe structural imbalances related to the cumulative impact of large budgetary deficits, rapid increase in domestic bank credit, a fixed exchange rate, high inflation, which authorities aimed controlling through price controls. These policies were exacerbated by a deterioration of capital equipment and inadequate prices incentives in agricultural and export sectors. As a result, real output in 1981 was 15 percent lower than its 1974 level. The situation deteriorated further towards the second half of the 1980's due to high fiscal deficits, financed primarily through domestic credit, directed credit policies (since 1981 banks were obliged to lend at least 20% of their portfolio to the agricultural sector), a deterioration in cocoa exports, and a large depreciation of the currenty (a 1173% depreciation took place in 1983). Banks experienced liquidity pressures, but in addition to that, there were defficiencies in banking supervision and regulation. As a result, 7 out of the 11 banks were insolvent and the problems were addressed by capitalization and purchase of NPL's. | AD4: Despite having stronger macroeconomic fundamentals than Thailand, Indonesia suffered a contagion effect from Thai Bath's devaluation in July-97. At the time the crisis hit, there were defficiencies in banking oversight and regulation, together with significant vulnerabilities of banks to market risk. While the first wave of effects were observed in August-1997, the true meltdown happened in early 1998 following systemicwide bank runs and a free fall of the Rupiah. The government declared a temporary blanquet guarantee and a bank restructuring package that ultimately implied the closure of more than 60 banks and gross outlays of over 50 percent of GDP. | AG4: The financial liberalization of the late 80's and early 90's led to a rapid acceleration of credit in a vulnerable banking system. The weakness of the financial system became apparent to the general public with the intervention of the Blaise Group in 1994, establishing the Financial Institutions Services Company (FIS) to handle its liquidation. Confronted with a weak banking system but also with a renewed acceleration of inflation rate—at 30 percent at end-1995--and the increased pace of devaluation of the currency, the government tightened monetary policy leading to a sharp increase in real interest rates from negative to positive 30 percent. In October 1995, Century National Bank ran into severe liquidity problems and later insolvency problems were revealed. By mid-1996 Century had accessed overdrafts in an amount of J$4.3 billion (2 percent of GDP). The government intervened the bank in July 1996. Meanwhile, a number of other financial institutions became affected, mainly insurance companies. In total, over 150 institutions were intervened, with the rehabilitation of non-banks costing over 11 percent of GDP. | AH4: The Japanese macroeconomic environment in the second half of the 1980's was characterized by above-trend economic growth and near-zero inflation. At the same time, during this period, financial liberalization accelerated. These environment contributed to general optimism about the economy and boosted asset prices and fueled rapid credit expansion (in particular consumer and real estate lending). However, banks' lending practices at the time were emphasizing market share and were mostly done on the basis of collateral rather than cash flow, which undermined lending standards as real estate prices climbed. The stock market peaked at the end of 1989 and then collapsed after the summer of 1990. The collapsed was followed by an economic recession and a drastic decline in real estate prices. They in turn caused a rapid deterioration of bank's asset quality and weakened other financial firms as well. The problems were exacerbated by the erosion of bank's capital base caused by the fall in stock prices held in banks' portfolios. Some consequences were felt as early as 1989 when banks begun being downgraded. Then some failures (mostly small institutions such as credit cooperatives) took place in early 1991, and the problem with the housing loan corporations (jusen) in 1995-1996. However, it wasn't until 1997 that the systemic proportions of the problem became evident when high profile financial institutions failed. | AJ4: The devaluation of the Thai baht in July 1997, the subsequent regional contagion, and the crash of the Hong Kong stock market sent shock waves to the Korean financial system. Korea’s exchange rate remained broadly stable through October 1997. However, the high level of short-term debt and the low level of usable international reserves made the economy increasingly vulnerable to shifts in market sentiment. While macroeconomic fundamentals continued to be favorable, the growing awareness of problems in the financial sector and in industrial groups (chaebols) increasingly led to the difficulties for the banks in rolling over their short-term borrowing. The high leverage ratios of the chaebols and their low profitability made them very vulnerable to any shock to their cash flow. The health of the banking system, in turn, was extremely dependent on the viability of the chaebols. Banks were highly exposed to them, both directly through loans and discounts, and indirectly through the guarantee of corporate bonds and commercial paper. | AK4: Until end-1994 problems in the Latvian banking sector were confined to insolvencies of some smaller banks. The growing distress in the Latvian banking system turned into a full-fledged crisis in April 1995, after the failure of some banks to complete audited reports for 1994. The published audited reports exposed the fragile situation of the banking system, as two-thirds of the audited banks recorded losses in 1994 and lacked an adequate capital base to provide a cushion against these losses. The losses were generally a result of poor lending decisions and disregard for prudential regulations. The major crisis evolved in the first half of 1995 and concerned Banka Baltija, the biggest credit institution of the country at the time. Banka Baltija held over a quarter of all assets and about 30% of all bank deposits in Latvia. The Latvian solution to system risk was based on enhanced regulation and supervision, and increased transparency, with minimum lender of last resort support from the central bank, no deposit insurance and no bail-outs. | AM4: In April 1994 Lithuania introduced a currency board regime. The litas was pegged to the U.S. dollar at a rate of USD 1 = LTL 4. Inflation subsequently fell from 45% in 1994 (year-end) to about 13% in 1996. Monetary tightening and the fading of speculative sources of earnings contributed to increasingly frequent liquidity problems in the course of 1994 and 1995. Whereas previously mostly smaller credit institutions had been affected, in the summer of 1995 two medium-sized private banks experienced serious liquidity bottlenecks. After receiving some liquidity assistance, one was closed and the other nationalized at end-1995. The deteriorating situation in the Lithuanian banking sector culminated into a crisis following the publication of on-site inspection results, in December 1995, for the largest and third largest private banks, Innovation Bank and Litimpeks Bank, and the subsequent suspension of these banks' operations. Immediately following the closure of the two banks, widespread and steady bank deposit withdrawals took place from the banks that continued to operate and large foreign exchange outflows occurred through the currency board against a background of political uncertainty. | AO4: The persistent pace of credit expansion at an annual rate of nearly 30 percent to the private sector, in particular to the property sector and for the purchase of stocks and shares, exposed the financial system to potential risks from price declines in property and other assets that occurred in 1997. In the wake of market turbulence and contagion effects in the second half of 1997, concerns among market participants about the true condition and resilience of the financial system increasingly became a central issue, highlighted by the known fragilities among finance companies. The authorities responded to market pressures initially through foreign exchange market intervention accompanied by an increase in interest rates, and by subsequently allowing the ringgit to depreciate. There were substantial outflows of capital, through commercial banks and sales of stocks by foreigners. | AP4: Since the mid-1980's Mexico had carried out an economic adjustment and structural reform process, aimed at achieving sustainable growth. In the early 90's, banks were reprivatized (they were nationalized during the 1982 crisis) as part of the structural reform process. However, by end-1994 a number of vulnerabilities built up and developed into a currency and a banking crisis. Different factors contributed to the crisis: a growing current account deficit, real appreciation of the peso, political developments (Chiapas and assasination of Donato Colosio), the rise of U.S. interest rates. They were aggravated by maturity and currency mismatches in public-debt management and unsound banking practices. A major collapse of the banking system was avoided through a series of policy measures that included a blanquet guarantee, recapitalization of banks, special lines of credit, intervention of 15 banks (1994-2001), and loan restructuring programs. | AQ4: Three banks—Banca de Economii (BEM), Banca Sociala, and Unibank— representing a third of the system were closed in October 2015, after being under special administration of the National Bank of Moldova (NBM) for almost one year. A first stage forensic audit revealed a well-orchestrated fraud by seemingly unrelated shareholders and highlighted the shortcomings in the regulatory and supervisory frameworks. A generalized run on deposits was avoided largely because of a full payout on withdrawn deposits, but there are concerns about the health of some banks. | AT4: The largest bank in Nicaragua, Interbank, was found to have committed fraud and therefore was intervened in August 2000. Following the intervention, full protection for its depositors was announced. However, withdrawals continued until the bank was finally resolved in Oct. 2000 through a P&A. Another institution ran into problems soon after the resolution of Interbank. Runs against other banks occurred in part because the authorities announced limited coverage of its depositors. However, in its resolution a few days later, all depositors were protected. Two institutions more were resolved a few months later. All banks were resolved under P&A's and a blanket guarantee was passed by law after the first two failures. | AV4: Financial deregulation undertaken during 1984-1987 led to a credit boom (with real rates of credit growth of 20% y-y), accompanied by a boom in both residential and non-residential real estate. In 1985 oil prices fell sharply, turning a 4.8 percent surplus in the current account into a 6.2% deficit in 1986 with ensuing pressures on the exchange rate. The resulting drain in reserves was sterilized via lending to banks, to avoid a sharp increase in interest rates. Meanwhile, rate increases by the Bundesbank following the reunification of Germany, forced Norway to keep interest rates high throughout the economic recession, which started in 1988. At the same time, in 1990, Norway decded to adopt Basel with full implementation expected as of end of 1992. Problems at small banks that began in 1988 were adressed via mergers and assistance from the guarantee fund, funded by banks. However, by 1990 the fund had been depleted and the financial condition at large banks began to deteriorate. The turmoil reached systemic proportions by October 1991, when the second and fourth largest banks had lost a considerable amount of equity. | AW4: During most of the 80’s the Paraguayan economy was characterized by financial controls and unstable macroeconomic environment. The change in political regime in 1989 brought about financial liberalization: elimination of interest rate controls, authorization of foreign currency loans by local banks for export and import-related activities, gradual reduction of reserve requiremetns, etc. These measures led to rapid growth of the financial system in terms of the number of institutions and their size. During the early nineties, the macroeconomic outlook of the country improved. However, the banking system remained undercapitalized and non-performing loans rose sharply, coupled together with insider lending practices. The weaknesses in the financial system were in part caused by the slow progress on banking supervision and enforcement of regulation during the liberalization process. Already in 1989, an assessment by the superintendency revealed that about one third of the banking system was insolvent. The crisis began in May 1995 when the third and fourth largest banks could not meet clearing obligations and were intervened. The first line of response was liquidity support. However, as the crisis unfolded, an important amount of unrecorded deposits were discovered. A blanket guarantee covering intervened banks was announced, but pressures remained because at first, the guarantee covered only legitimate deposits, although later, all deposits were protected. Through a series of interventions, closures and substantial liquidity support, the distress period lasted until 1999. In the end, between 1995-1999, 15 out of the 19 locally-owned banks were either closed or absorbed by stronger institutions. By 1999 banks were predominantly foreign owned. | AX4: By mid-1997 the peso had appreciated by over 25 percent in real effective terms since 1993 and the external current account deficit had widened to over 5 percent of GNP. Large external borrowing in 1996, especially by banks, had raised foreign currency debt exposures, including on short-term debt which, at around $10 billion, was about equal the level of usable gross official reserves. Private sector credit had expanded very rapidly during 1995-96 including a significant rise in credit to real estate and consumption. From early 1997, economic conditions deteriolated as the regional downturn interacted with the country’s own vulnerabilities. A decline in capital inflows and a slowdown in manufacturing output combined with sharp falls in the stock market and mounting pressures on the peso. The authorities initially responded by tightening monetary policy and by intervention to maintain the de facto peg of the peso. When this stance became unsustainable in the aftermath of the float of the Thai baht, the peso was floated on July 11, accompanied by a strengthening of fiscal, monetary, and structural policies including regulation and supervision of the banking sector. The overall effects were mild compared to those experienced by its neighbors. Only a handful of institutions was closed and one large bank ran into trouble (PNB-partially state-owned) but was later privatized in 2000. No public funds were used in the restructuring, except for liquidity support. | AZ4: Initially, from mid-1997 to April 1998, the Central Bank of Russia (CBR) was relatively successful in defending the fixed exchange rate policy through a significant tightening of credit. However, the situation became increasingly untenable when significant political turmoil in Russia-starting with the President’s dismissal of the government of Prime Minister Chernomyrdin and prolonged by a stalemate over the formation of a new cabinet-cast increasing doubt on the political resolve to come to grips with Russia’s fiscal problems. From mid-July, when the Duma refused to pass key fiscal measures, the situation deteriorated rapidly, leading to a unilateral restructuring of ruble-denominated treasury bills and bonds on August 17, 1998. The ruble was allowed to float three days later despite previous announcements that it wouldn't be devalued. A large devaluation in real effective terms (over 300% in nominal terms), loss of access to international capital markets, and massive losses to the banking system ensued. However, well before the crisis, there was widespread recognition that the banking system had a series of weaknesses. In particular, bank reporting and bank supervision were weak, there was an excessive exposure to foreign exchange rate risk, connected lending, and poor management. Two key measures implemented were a 90-day moratorium on foreign liabilities of banks and the transfer of a large fraction of deposits from insolvent banks to Sberbank. Most of the crisis was handled through assistance from the Central Bank. | BD4: Economic performance at the end of the 80’s was marred by low economic growth, rising inflation, and a weakening balance of payments. Underlying this deterioration was a large overall government deficit attributable to the worsening security conditions and to revenue shortfalls and expenditure overruns, especially on wages and salaries. The larger deficit resulted in heavy recourse to domestic bank borrowing (5 percent of GDP), a 33 percent rise in reserve money, and an accelerating loss of reserves toward the end of the year as confidence waned. As financial imbalances persisted into 1989 the Government made continued heavy recourse to bank credit, particularly from the Central Bank, and the demand effect was accentuated by substantial bank financing of the public enterprises. These events raised a number of vulnerabilities and inefficiencies at two large state banks (2/3 of industry’s assets) Bank of Ceylon and the People's Bank. The government decided to recapitalized them in 1993 to solve their solvency problem due to high nonperforming assets. | BE4: As in the case of Finland and Norway, the pre-crisis period was characterized by rapid lending expansion following financial liberalization. As the other countries, Sweden was affected by the adverse consequences of higher German interest rates. The first bank in trouble was Forsta sparbanken (the country's largest savings bank) in the fall of 1991. Later in 1991, Nordbanken got in problems (3rd largest), 71% state-owned. The problems spread to other institutions until it reached systemic proportions in the fall of 1992, when a blanket guarantee was announced. | BH4: Under the framework of a pegged exchange rate regime, Thailand had enjoyed a decade of robust growth performance, but by late 1996 pressures on the baht emerged. Pressure increased through the first half of 1997 amidst an unsustainable current account deficit, a significant appreciation of the real effective exchange rate, rising short-term foreign debt, a deteriorating fiscal balance, and increasingly visible financial sector weaknesses, including large exposure to the real estate sector, exchange rate risk and liquidity risk. Finance companies had disproportionately the largest exposure to the property sector and were the first institutions affected by the economic downturn. Following mounting exchange rate pressures and ineffective interventions to alleviate these pressures, the baht was floated on July 2, 1997. In light of weak supportive policies, the baht depreciated by 20 percent against the U.S. dollar in July. | BI4: Turkey had accumulated important macroeconomic imbalances throughout the 90's, inflation had been hovering around 80%, high fiscal deficits and public debt, high current account deficit, and weak financial system. Banks had a high exposure to the government through large holdings of public securities, sizeable maturities and exchange rate risk missmatches, making them highly vulnerable to market risk. In Nov 2000, one large bank cut its credit lines to a few smaller banks, who in turn reacted by liquidating public securities in the market. A sharp drop in price of such securities caused panic among foreign investors triggering a reversal in capital flows and a sharp increases in interest rates and declines in the value of the currency. | BJ4: Vulnerabilities in Ukrainian banks had their roots in the transition process, with bad loans inherited from old state banks, extended during the Central Planning system. Directed credit to state-owned companies, with no repayment capacity, and the government not honoring existing debt caused banks severe solvency problems, which were magnified by unsound lending practices. Public confidence on the banking system deteriorated with the crisis in Russia. Interest rates in the interbank money market increased sharply, the value of securities fell on the secondary market, liquidity became scarce, and depositors started to withdraw money from their accounts. | BO4: Deposits were highly dollarized and an important fraction was of non-residents (deposits/GDP was 75% as of 2001). The introduction of capital controls and deposit freezes in Argentina in Dec. 2001 triggered liquidity problems at the two largest private banks Banco Galicia Uruguay (BGU) and Banco Comercial (BC) (with combined assets of 20 percent of the total) as a result of their high level of exposure to Argentina (owned by Argentinean financial groups). In January 2002 alone, BGU lost 15% of deposits (its business model consisted in taking deposits from argenteneans and lending to them as well). BGU was intervened in February and later suspended. Similarly, BC had large holdings of Argentine government debt as well as extensive lending to the Argentina conglomerate Grupo Banco General de Negocios, of which BC was a member. Its problems were exacerbated by fraudulent activities. A second wave of deposit withdrawals ensued in April 2002, following Uruguay’s downgrade from investment grade status. By May, the runs expanded to the public banks, (Republica and Hipotecario) accounting for 40 percent of the system’s assets, which were at a weak condition, with NPL's of 39% as of 2001, compared to 5.6% at private banks. By July, NIR had dropped in 80% and deposits in 38% vis-a-vis Dec. 2001. | BP4: During the 80's the Venezuelan economy was characterized by poor economic performance, with real gdp growh averaging 1% during 1980-88, only a fourth of the speed of growth during the previous decade. Starting in 1989, the economy entered a new phase with a major program of macroeconomic adjustment and reform. However, the reforms did not progress as quickly as expected and the government resorted heavily to keeping the exchange rate stable to alleviate inflationary pressures. 2 coup attempts in 1991 triggered substantial pressures on the exchange rate market, leading to high interest rates and important NIR declines. As a result, the currency depreciated sharply towards the end of 1992. A weak oil market, a persistently laxed fiscal policy, high interest rates, and increased political tensions exacerbated problems while asset quality at banks deteriorated sharply. The trigger of the crisis was the closure of Banco Latino (2nd largest in terms of deposits), in mid-January 1994. In total, 19 banks (55% of system's deposits) were either nationalized or closed. | BQ4: Signs of stress in the banking sector were growing since 1996. Overdue loans had officially risen to 15 percent of total credit (5 percent of GDP), and would have been higher using internationally-accepted standards. Two of the four large state-owned banks suffered corruption scandals. A number of the small joint-stock banks, which made up about 20 percent of the banking system, had difficulty servicing letters of credit.
A5: Institutions
A6: Deposit insurance(Y/N) | B6: Y | C6: Y | D6: Y | E6: Y | F6: Y | G6: Y | H6: N | I6: N | J6: N | K6: Y | L6: N | M6: N | N6: Y | O6: N | P6: Y | Q6: Y | R6: Y | S6: Y | T6: N | U6: Y | V6: N | W6: Y | X6: Y | Y6: Y | Z6: N | AA6: Y | AB6: Y | AC6: Y | AD6: N | AE6: Y | AF6: Y | AG6: N | AH6: Y | AI6: Y | AJ6: Y | AK6: N | AL6: Y | AM6: N | AN6: Y | AO6: N | AP6: Y | AQ6: Y | AR6: Y | AS6: Y | AT6: N | AU6: Y | AV6: Y | AW6: N | AX6: Y | AY6: Y | AZ6: N | BA6: Y | BB6: Y | BC6: Y | BD6: Y | BE6: N | BF6: Y | BG6: Y | BH6: N | BI6: Y | BJ6: Y | BK6: Y | BL6: Y | BM6: Y | BN6: Y | BO6: Y | BP6: Y | BQ6: N
A7: Year of creation | B7: 1979 | C7: 1979 | D7: 1979 | E7: 1979 | K7: 1996 | N7: 1988 | P7: 1997 | Q7: 1994 | U7: 1998 | W7: 1969 | AH7: 1971 | AJ7: 1996 | AP7: 1986 | AQ7: 2004 | AV7: 1961 | AX7: 1963 | BD7: 1987 | BI7: 1983 | BJ7: 1998 | BO7: 2002 | BP7: 1985
A8: Coverage at start of crisis
A9: In local currency | B9: Full | C9: Full | D9: 30000 | E9: 30000 | F9: 20000 | G9: 20000 | H9: 0 | I9: 0 | J9: 0 | K9: 5000 | L9: 0 | M9: 0 | N9: 10000000 | O9: 0 | P9: 50000 | Q9: 100000 | R9: 100000 | S9: 300000 | T9: 0 | U9: 7416 | V9: 0 | W9: Full | X9: 70000 | Y9: 20000 | Z9: 0 | AA9: 20000 | AB9: 6000000 | AC9: Unlimited | AD9: 0 | AE9: 20000 | AF9: 103291 | AG9: 0 | AH9: Full | AI9: 700000 | AJ9: 20000000 | AK9: 0 | AL9: 20000 | AM9: 0 | AN9: 20000 | AO9: 0 | AP9: Full | AQ9: 6000 | AR9: 0 | AS9: 20000 | AT9: 0 | AV9: Full | AW9: 0 | AX9: 10000 | AY9: 25000 | AZ9: 0 | BA9: 400000 | BB9: 22000 | BC9: 20000 | BD9: 100000 | BE9: 0 | BF9: 250000 | BG9: 30000 | BH9: 0 | BI9: Full | BJ9: 1200 | BK9: 50000 | BL9: 200000 | BM9: 35000 | BN9: 100000 | BO9: 100000 | BP9: 250000 | BQ9: 0
A10: In percent of GDP per capita | D10: 4.04 | E10: 4.19 | F10: 0.61032922 | G10: 0.63420923 | H10: 0 | I10: 0 | J10: 0 | K10: 2.37 | L10: 0 | M10: 0 | N10: 3.29 | O10: 0 | P10: 1.8 | Q10: 0.75 | R10: =100000/22606 -> 4.4236044 | S10: 0.96864234 | T10: 0 | U10: 3.81 | V10: 0 | X10: 2.2876215 | Y10: 0.67642141 | Z10: 0 | AA10: 0.9885985 | AB10: 2.3679784 | AD10: 0 | AE10: 0.45922573 | AF10: 3.9665132 | AG10: 0 | AI10: 0.8435108 | AJ10: 2.18 | AK10: 0 | AL10: 3.0800125 | AM10: 0 | AN10: 0.25622995 | AO10: 0 | AQ10: 0.21 | AR10: 0 | AS10: 0.57614676 | AT10: 0 | AU10: 0 | AW10: 0 | AX10: 3.22 | AY10: 1.5717263 | AZ10: 0 | BA10: 1.7096015 | BB10: 1.284378 | BC10: 0.85262024 | BD10: 7.18 | BE10: 0 | BF10: 0.73160903 | BG10: 0.43472128 | BH10: 0 | BJ10: 0.59 | BK10: 3.2265401 | BL10: 6.19 | BM10: 1.5999242 | BN10: 2.2389661 | BO10: 1.4 | BP10: 0.96 | BQ10: 0
A11: Containment phase
A12: Deposit freeze and bank holiday
A13: Deposit freeze (Y/N) | B13: N | C13: Y | D13: N | E13: Y | F13: N | G13: N | H13: N | I13: Y | J13: N | K13: N | L13: N | M13: N | N13: N | O13: N | P13: N | Q13: N | R13: Y | S13: N | T13: N | U13: Y | V13: N | W13: N | X13: N | Y13: N | Z13: N | AA13: Y | AB13: N | AC13: N | AD13: N | AE13: N | AF13: N | AG13: N | AH13: N | AI13: N | AJ13: N | AK13: N | AL13: Y | AM13: N | AN13: N | AO13: N | AP13: N | AQ13: N | AR13: N | AS13: N | AT13: N | AU13: N | AV13: N | AW13: N | AX13: N | AY13: N | AZ13: N | BA13: N | BB13: N | BC13: N | BD13: N | BE13: N | BF13: N | BG13: N | BH13: N | BI13: N | BJ13: N | BK13: N | BL13: Y | BM13: N | BN13: N | BO13: Y | BP13: N | BQ13: N
A14: Introduction | C14: 32870 | E14: 37228 | I14: 32933 | R14: 41361 | U14: 36231 | AA14: 42205 | AL14: 39783 | BL14: 41699 | BO14: 37473
A15: Duration (in months) | C15: 120 | E15: 12 | I15: 29 | R15: 14 | U15: 6 | AA15: Partially in place | AL15: 6 | BL15: 40 | BO15: 36
